Workbook

Sheet 00_Cover
A1: ="RAB dan Model Investasi — Agroforestri "&'02_Assumptions'!$C$6&" ha" -> RAB dan Model Investasi — Agroforestri 100 ha
A2: Mode dua penggerak: ubah luas kebun dan jumlah lokasi. Asumsi harga/biaya tetap dapat disesuaikan bila tersedia quotation baru.
A4: Tujuan
A5: Workbook ini menghitung seleksi lahan, pembukaan tanpa bakar, infrastruktur, bibit, alat dan mesin, input pertanian, HOK, pemeliharaan, sertifikasi, produksi, pendapatan, dan arus kas 10 tahun untuk kebun agroforestri terpadu.
A6: Model membandingkan satu lokasi dengan empat lokasi. Model ini adalah alat perencanaan investasi, bukan pengganti uji legal, tanah/air, desain teknik, diagnosis kesehatan tanaman, label pestisida, atau penawaran pemasok.
A7: Desain dasar memakai satu matriks areal efektif: kelapa, durian, dan pisang ditanam bersama; gamal, Indigofera, serai wangi, penutup tanah, dan strip biodiversitas tersebar di lorong/kontur. Tidak ada blok komoditas terpisah.
A9: Cara menggunakan
A10: 1 | B10: Untuk simulasi cepat, ubah hanya 02_Assumptions!C6 (luas) dan C8 (jumlah lokasi). Semua volume dan total mengikuti otomatis.
A11: 2 | B11: Jumlah lokasi dapat dipilih 1–4; biaya berbasis lokasi dan kebutuhan alat/staf dihitung ulang otomatis.
A12: 3 | B12: Harga satuan, upah, tarif sewa, dan biaya lain tetap terbuka sebagai asumsi opsional—ubah hanya bila memiliki dasar yang lebih baik.
A13: 4 | B13: Jangan mengetik ulang populasi, volume input, HOK, kru, atau total biaya: sel tersebut adalah hasil formula.
A14: 5 | B14: Ganti harga asumsi dengan sedikitnya tiga penawaran yang setara dan dokumentasikan pilihan.
A15: 6 | B15: Baca 15_Pemeriksaan dan peringatan sebelum memakai hasil investasi.
A16: 7 | B16: Buka 18_Panduan_Per_Sheet untuk paparan tujuan, cara membaca, input, keterkaitan, dan keputusan pada setiap sheet.
A18: Legenda warna
A19: Jingga dengan angka biru | B19: Dua penggerak utama: luas dan jumlah lokasi
A20: Kuning muda dengan angka biru | B20: Asumsi opsional (harga, tarif, dosis, produktivitas); sudah terisi dan tidak wajib diubah
A21: Hijau muda | B21: Rumus/hasil otomatis—jangan ditimpa
A22: Catatan jingga/merah | B22: Risiko, batasan, atau konfirmasi wajib
A23: Total hijau | B23: Subtotal atau hasil utama
A26: Pengecualian dan kondisi utama
A27: Akuisisi/sewa lahan masih Rp0 sampai tersedia calon lahan dan uji legal/valuasi.
A28: PPN, pajak badan, pembiayaan, penyusutan, pajak transaksi tanah, dan pabrik pengolahan tidak termasuk.
A29: Proyek mengasumsikan lahan pertanian terdegradasi/non-hutan. Konversi hutan alam, kawasan lindung, atau HCV adalah Tidak Layak.
A30: Input sintetis berhenti setelah fase transisi yang ditentukan; klaim organik memerlukan penetapan LSO.
A31: Pendapatan tingkat kebun dan tanpa premi. Pendapatan nanas/tambahan hanya masuk bila diaktifkan; manfaat penutup tanah tidak dimonetisasi.
A32: Harga adalah asumsi perencanaan 2026. Baris berkeyakinan rendah memerlukan penawaran; hasil biologis memerlukan validasi lapangan.

Sheet Panduan_Per_Sheet
A1: Panduan Membaca Setiap Sheet
A2: Panduan ini memakai mode dua penggerak: luas kebun dan jumlah lokasi. Asumsi harga/biaya tetap bisa diubah secara opsional; semua output lainnya mengikuti formula.
A5: Alur penggunaan yang disarankan
A6: 1 | B6: Orientasi | C6: 00_Cover → 18_Panduan_Per_Sheet → 01_Dashboard | D6: Pahami ruang lingkup, batasan, cara kerja model, dan posisi ekonomi awal sebelum mengubah angka.
A7: 2 | B7: Tetapkan dasar | C7: 02_Assumptions → 03_Land_Screening → 04_Planting_Design | D7: Masukkan penggerak proyek, saring calon lahan, lalu periksa desain populasi agroforestri terpadu.
A8: 3 | B8: Bangun anggaran | C8: 05_Workplan_Labor → 06_Equipment_Tools → 07_Agri_Inputs → 08_CAPEX_RAB → 09_OPEX_10Y → 14_Certification_ESG → 17_Model_Fleksibel → 20_Operasi_Efisien | D8: Validasi volume kerja, alat, input, investasi, biaya tahunan, kewajiban sertifikasi, dan kebutuhan tambahan.
A9: 4 | B9: Uji hasil dan putuskan | C9: 10_Production_Revenue → 11_Cash_Flow → 19_Optimasi_10Tahun → 21_Pendapatan_Tambahan → 13_Sensitivity → 15_Checks → 16/22_Sources | D9: Nilai produksi, arus kas, biaya fragmentasi, ketahanan skenario, integritas rumus, dan kekuatan bukti.
A11: No. | B11: Nama sheet | C11: Tujuan/fungsi | D11: Cara membaca | E11: Input dan keterkaitan | F11: Keputusan/peringatan
A12: 1 | B12: 00_Cover | C12: Halaman pembuka dan batas penggunaan model. | D12: Baca tujuan, konsep agroforestri terpadu, legenda warna, cara penggunaan, dan pengecualian. Sheet ini menjelaskan apa yang dihitung dan apa yang belum termasuk. | E12: Tidak ada perhitungan utama yang perlu diubah di sini. Cover mengarahkan pengguna ke asumsi, pemeriksaan, sumber, dan panduan. | F12: Pastikan seluruh pengguna menyepakati ruang lingkup sebelum menggunakan angka untuk persetujuan investasi.
A13: 2 | B13: 01_Dashboard | C13: Ringkasan eksekutif investasi dan operasi. | D13: Mulai dari luas bruto/efektif, investasi awal, pendanaan puncak, NPV/IRR, populasi, dan kru puncak. Lanjutkan ke grafik pendapatan, arus kas tahunan, arus kas kumulatif, serta perbandingan satu dan empat lokasi. | E13: Menarik hasil dari 02, 04, 05, 08, 09, 10, 11, dan 12. Tidak untuk diisi manual. | F13: NPV negatif atau pengembalian lewat Tahun 10 menunjukkan kebutuhan optimasi desain, produktivitas, harga, pasar, atau horizon—bukan alasan menghapus drainase, biosekuriti, atau mutu bibit.
A14: 3 | B14: 02_Assumptions | C14: Pusat kendali seluruh penggerak model. | D14: Baca per kelompok: proyek/finansial, luas, kepadatan, harga bibit dan hasil, tenaga kerja, produktivitas, input, sertifikasi, serta faktor skenario. Sel kuning dengan angka biru adalah input; sel hijau adalah rumus tertaut. | E14: Luas bruto, area efektif, jumlah lokasi, kerapatan, harga, upah, inflasi, dosis, survival, yield, dan fase sintetis mengubah hampir seluruh sheet. | F14: Ganti asumsi berkeyakinan rendah dengan hasil survei, uji laboratorium, kontrak pembeli, dan penawaran pemasok. Hindari menimpa sel formula.
A15: 4 | B15: 03_Land_Screening | C15: Menyeleksi calon lahan dan menghentikan lokasi berisiko tinggi. | D15: Isi skor 1–5 hanya jika tersedia bukti. Bandingkan skor berbobot calon A–D, lalu periksa gerbang legal, HCV/hutan, banjir, air, penyakit pisang, dan lereng. Bagian terakhir menunjukkan proses uji tuntas empat minggu. | E15: Skor dan status calon lahan diisi pengguna. Hasilnya menjadi dasar sebelum biaya pembukaan, survei detail, dan desain final dikeluarkan. | F15: Setiap gerbang Tidak Layak mengalahkan skor agregat. Tidak ada calon yang boleh dianggap siap hanya karena nilai totalnya tinggi.
A16: 5 | B16: 04_Planting_Design | C16: Mengubah luas menjadi populasi dan kebutuhan bibit dalam satu matriks agroforestri. | D16: Periksa area efektif, kerapatan dan populasi kelapa, durian, pisang, gamal, Indigofera, serai wangi, penutup tanah, serta opsi. Lihat kebutuhan cadangan, bibit dibeli, tanaman hidup, harga, dan total pengadaan. | E16: Mengikuti luas efektif, kerapatan, cadangan bibit, survival, dan harga dari 02 serta opsi dari 17. Mengalir ke HOK, input, CAPEX, produksi, dan revenue. | F16: Populasi adalah rancangan awal. Finalisasi jarak dan posisi di lapangan berdasarkan kontur, cahaya, air, akses, dan ukuran tajuk dewasa; bukan membagi kebun menjadi blok komoditas.
A17: 6 | B17: 05_Workplan_Labor | C17: Menghitung urutan pekerjaan, HOK, durasi, dan kebutuhan kru. | D17: Baca pekerjaan Tahun 0 dari asesmen sampai penanaman, kemudian HOK bulanan dan pemeliharaan tahunan. Total HOK dibagi hari kerja untuk memperoleh kru rata-rata; kru puncak memasukkan faktor kebutuhan puncak. | E17: Jumlah pekerjaan mengikuti luas, populasi, unit infrastruktur, dan lokasi. HOK/unit, upah, hari kerja, serta faktor puncak berasal dari 02 dan baris tambahan dari 17. | F17: Gunakan untuk rencana rekrutmen, kontraktor, mobilisasi, dan kalender kerja. Pastikan tarif kontraktor yang sudah termasuk tenaga tidak dihitung kembali sebagai HOK langsung.
A18: 7 | B18: 06_Equipment_Tools | C18: Merinci alat produksi, mesin, kendaraan, APD, dan penggantian. | D18: Untuk setiap item, lihat kategori, fungsi, jumlah per 100 ha, jumlah minimum per lokasi, unit, harga, total satu/empat lokasi, umur pakai, siklus penggantian, dan kenaikan akibat lokasi tambahan. | E18: Jumlah mengikuti luas dan lokasi; harga serta umur pakai dapat diubah. Total alat mengalir ke CAPEX dan penggantian/perawatan OPEX. | F18: Tentukan beli atau sewa berdasarkan jam pakai, dukungan servis, akses suku cadang, dan risiko alat menganggur. Validasi spesifikasi dengan kondisi lereng, jalan, dan air.
A19: 8 | B19: 07_Agri_Inputs | C19: Menghitung input pertanian per tahun secara terperinci. | D19: Baca komoditas, jenis input, alasan penggunaan, dosis, frekuensi, harga, serta jumlah dan biaya Tahun 1–10. Baris total merangkum kebutuhan input tahunan seluruh sistem agroforestri. | E19: Volume mengikuti luas/populasi yang memenuhi syarat, tanaman hidup, dosis, frekuensi, fase umur, inflasi, dan penghentian input sintetis. Opsi aktif dari 17 ikut masuk. | F19: Dosis adalah allowance perencanaan. Uji tanah, daun, air, riwayat lahan, diagnosis OPT, label resmi, masa tunggu, dan standar organik harus menentukan aplikasi nyata.
A20: 9 | B20: 08_CAPEX_RAB | C20: Menggabungkan seluruh investasi awal proyek. | D20: Telaah per tahap: lahan/asesmen, survei, persiapan, tanah, jalan/drainase, batas, fasilitas, mobilisasi, penanaman, alat, sistem, dan cadangan. Bandingkan total satu lokasi, empat lokasi, dan skenario terpilih. | E20: Menarik jumlah dan harga dari 02, 04, 05, 06, 14, dan 17. Jumlah lokasi menggandakan komponen yang minimum per lokasi atau mengikuti perimeter/mobilisasi. | F20: Biaya lahan masih Rp0 sampai ada objek nyata. Gunakan BOQ teknik dan sedikitnya tiga quotation untuk item material; cegah duplikasi tenaga, alat, atau fasilitas.
A21: 10 | B21: 09_OPEX_10Y | C21: Menghitung biaya operasional nominal selama 10 tahun. | D21: Baca total tahunan menurut staf tetap, HOK, input, perawatan, penggantian alat, pengendalian gulma, panen, sertifikasi, serta biaya tambahan. Bagian staf menunjukkan jabatan dan perbedaan kebutuhan satu/empat lokasi. | E21: Mengikuti upah, inflasi, jumlah lokasi, HOK, input, aset, panen, sertifikasi, dan baris tambahan aktif. Menjadi pengurang pada arus kas. | F21: Bedakan biaya tetap, biaya berbasis luas, biaya berbasis lokasi, dan biaya variabel panen. Gunakan angka nominal untuk kebutuhan kas dan jangan mencampurnya dengan harga riil tanpa penyesuaian.
A22: 11 | B22: 10_Production_Revenue | C22: Memproyeksikan hasil dan pendapatan tiap komoditas. | D22: Untuk pisang, kelapa, durian, dan opsi tambahan, baca populasi hidup, hasil per tanaman/rumpun menurut umur, harga tingkat kebun, pendapatan per tahun, serta biaya panen variabel. | E22: Mengikuti tanaman hidup dari 04/17, kurva hasil, harga, eskalasi, survival, dan status aktif. Total pendapatan masuk ke 11; biaya panen masuk ke OPEX. | F22: Tidak ada premi organik dalam kasus dasar. Konfirmasi varietas, naungan, pola produksi, mutu, kehilangan panen, kapasitas pasar, dan kontrak offtake sebelum mengandalkan proyeksi.
A23: 12 | B23: 11_Cash_Flow | C23: Mengukur kebutuhan kas dan kelayakan finansial proyek. | D23: Arus kas proyek = pendapatan dikurangi OPEX dan CAPEX. Baca arus kas tahunan, kumulatif, NPV pada tingkat diskonto, IRR bila tersedia, tahun pengembalian, pendanaan puncak, dan rasio manfaat-biaya terdiskonto. | E23: Menarik CAPEX dari 08, OPEX dari 09, revenue dari 10, dan tingkat diskonto dari 02. Semua perubahan penggerak utama mengalir ke hasil ini. | F23: Gunakan NPV untuk keputusan ekonomi dan pendanaan puncak untuk kebutuhan modal. Jika arus kas tidak berganti tanda secara valid, IRR dapat tidak bermakna; jangan memaksakan interpretasi.
... A34: 22 | B34: 22_Sumber_Optimasi | C34: Mendokumentasikan bukti dan tingkat keyakinan seluruh pengungkit optimasi. | D34: Cari ID OPT/ASM dari sheet 20–21, baca URL, cara penerapan, dan validasi wajib. | E34: Tidak ada rumus utama; tambahkan hasil quotation, kontrak, demplot, dan MRV. | F34: ASM-QUOTE/RISK/PILOT bukan fakta pasar dan tidak boleh dipakai sebagai approval final.
A36: Prinsip penggunaan setelah optimasi
A37: Target untung Tahun 10 dibangun dari penghematan yang dapat ditelusuri dan pendapatan yang dikenai biaya, mass balance, serta haircut risiko. Untuk keputusan bankable, nolkan pendanaan yang belum dikontrak, ganti quotation rendah-keyakinan, dan jalankan kembali 19_Optimasi_10Tahun serta 15_Checks.

Sheet 01_Dashboard
A1: ="Ringkasan Investasi Agroforestri "&'02_Assumptions'!$C$6&" ha — "&'02_Assumptions'!$C$8&" lokasi" -> Ringkasan Investasi Agroforestri 100 ha — 1 lokasi
A2: Cukup ubah dua penggerak pada 02_Assumptions: luas kebun dan jumlah lokasi. Harga/biaya dapat disesuaikan secara opsional; seluruh KPI mengikuti rumus.
A4: Keluaran skenario optimasi aktif
A5: Luas bruto / efektif | E5: Investasi awal optimasi | I5: Pendanaan puncak optimasi
A6: ='02_Assumptions'!$C$6 -> 100 | E6: ='19_Optimasi_10Tahun'!$C$6 -> 14576030480 | I6: ='19_Optimasi_10Tahun'!$C$13 -> 1.7456171e+10
A7: ='02_Assumptions'!$C$6*'02_Assumptions'!$C$7 -> 88 | E7: ="Skenario: "&'02_Assumptions'!$C$8&" lokasi" -> Skenario: 1 lokasi | I7: =IF(ISNUMBER('19_Optimasi_10Tahun'!$C$14),"Balik modal: Tahun "&'19_Optimasi_10Tahun'!$C$14,"Balik modal: "&'19_Optimasi_10Tahun'!$C$14) -> Balik modal: Tahun 10
A9: NPV / IRR optimasi | E9: Pohon kelapa / durian | I9: Rumpun pisang awal / kru puncak T0
A10: ='19_Optimasi_10Tahun'!$C$11 -> -9.4097266e+09 | E10: ='04_Planting_Design'!$D$8 -> 7304 | I10: ='04_Planting_Design'!$H$8 -> 44000
A11: ='19_Optimasi_10Tahun'!$C$12 -> 0.009061345 | E11: ='04_Planting_Design'!$F$8 -> 2640 | I11: ='05_Workplan_Labor'!$Z$27 -> 70.060267
A13: Model otomatis: matriks agroforestri, nanas, penutup tanah legum, input pertanian, kompos internal, PHT, alat beli/sewa, tenaga kerja, kemitraan, dan diversifikasi kelapa mengikuti luas serta jumlah lokasi.
A15: Titik keputusan
A16: Konfigurasi yang disarankan | B16: Satu lokasi berdekatan seluas 100 ha | C16: Empat lokasi menduplikasi perimeter, sarana, alat, staf, dan logistik
A17: Persetujuan lahan | B17: Belum ada calon lahan yang dinyatakan siap | C17: Selesaikan uji legal, HCV/sosial, tanah, air, lereng, banjir, dan penyakit pisang
A18: Jalur organik | B18: Masa transisi, bukan klaim langsung | C18: Input sintetis berhenti sesuai pengaturan; LSO menentukan kelayakan
A19: Disiplin pendapatan | B19: Tanpa premi organik; opsi hanya masuk bila aktif | C19: Pastikan offtake tingkat kebun dan spesifikasi mutu sebelum keputusan akhir
A20: Penggerak nilai terbesar | B20: Durian mulai T5 | C20: Juga asumsi biologis dan harga yang paling berisiko
A21: Penggerak survival yang dapat dikendalikan | B21: Drainase, air, bibit bebas penyakit, QC pembibitan, dan sulaman | C21: Jangan mengurangi pengendali tersebut demi memperbaiki NPV
A24: Pendapatan tahunan dan arus kas skenario optimasi
A25: Tahun | B25: Total pendapatan | C25: Arus kas proyek | D25: Arus kas kumulatif
A26: Y1 | B26: ='19_Optimasi_10Tahun'!$C$18 -> 5263368000 | C26: ='19_Optimasi_10Tahun'!$C$21 -> 370949900 | D26: ='19_Optimasi_10Tahun'!$C$22 -> -14205080580
A27: Y2 | B27: ='19_Optimasi_10Tahun'!$D$18 -> 4844326080 | C27: ='19_Optimasi_10Tahun'!$D$21 -> -36793954 | D27: ='19_Optimasi_10Tahun'!$D$22 -> -1.4241875e+10
A28: Y3 | B28: ='19_Optimasi_10Tahun'!$E$18 -> 3.3874715e+09 | C28: ='19_Optimasi_10Tahun'!$E$21 -> -7.9396498e+08 | D28: ='19_Optimasi_10Tahun'!$E$22 -> -1.503584e+10
A29: Y4 | B29: ='19_Optimasi_10Tahun'!$F$18 -> 2.7035314e+09 | C29: ='19_Optimasi_10Tahun'!$F$21 -> -1.2737051e+09 | D29: ='19_Optimasi_10Tahun'!$F$22 -> -1.6309545e+10
A30: Y5 | B30: ='19_Optimasi_10Tahun'!$G$18 -> 3.2155436e+09 | C30: ='19_Optimasi_10Tahun'!$G$21 -> -1.1466268e+09 | D30: ='19_Optimasi_10Tahun'!$G$22 -> -1.7456171e+10
A31: Y6 | B31: ='19_Optimasi_10Tahun'!$H$18 -> 4.5804146e+09 | C31: ='19_Optimasi_10Tahun'!$H$21 -> 2.357133e+08 | D31: ='19_Optimasi_10Tahun'!$H$22 -> -1.7220458e+10
A32: Y7 | B32: ='19_Optimasi_10Tahun'!$I$18 -> 6.6688587e+09 | C32: ='19_Optimasi_10Tahun'!$I$21 -> 2.0758383e+09 | D32: ='19_Optimasi_10Tahun'!$I$22 -> -1.514462e+10
A33: Y8 | B33: ='19_Optimasi_10Tahun'!$J$18 -> 8.8586285e+09 | C33: ='19_Optimasi_10Tahun'!$J$21 -> 3.7019262e+09 | D33: ='19_Optimasi_10Tahun'!$J$22 -> -1.1442694e+10
A34: Y9 | B34: ='19_Optimasi_10Tahun'!$K$18 -> 1.0917408e+10 | C34: ='19_Optimasi_10Tahun'!$K$21 -> 5.7209427e+09 | D34: ='19_Optimasi_10Tahun'!$K$22 -> -5.7217508e+09
A35: Y10 | B35: ='19_Optimasi_10Tahun'!$L$18 -> 1.2630618e+10 | C35: ='19_Optimasi_10Tahun'!$L$21 -> 7.0597476e+09 | D35: ='19_Optimasi_10Tahun'!$L$22 -> 1.3379968e+09
A38: Pembanding baseline 1 lokasi dan 4 lokasi — sebelum paket optimasi
A39: Ukuran | B39: 1 lokasi | C39: 4 lokasi | D39: Selisih | E39: Makna
A40: Investasi awal | B40: ='12_Scenario_1v4'!$B$5 -> 15268150480 | C40: ='12_Scenario_1v4'!$C$5 -> 2.3875151e+10 | D40: =C40-B40 -> 8.6070007e+09 | E40: Duplikasi sarana
A41: OPEX 10 tahun | B41: ='12_Scenario_1v4'!$B$7 -> 4.8615696e+10 | C41: ='12_Scenario_1v4'!$C$7 -> 6.2902563e+10 | D41: =C41-B41 -> 1.4286867e+10 | E41: Tambahan staf/logistik
A42: NPV | B42: ='12_Scenario_1v4'!$B$8 -> -1.1872485e+10 | C42: ='12_Scenario_1v4'!$C$8 -> -2.8601005e+10 | D42: =C42-B42 -> -1.672852e+10 | E42: Hasil keputusan
A43: Pendanaan puncak | B43: ='12_Scenario_1v4'!$B$11 -> 1.9597093e+10 | C43: ='12_Scenario_1v4'!$C$11 -> 3.6542781e+10 | D43: =C43-B43 -> 1.6945688e+10 | E43: Kebutuhan kas
A46: Skenario Optimasi 10 Tahun — baca bersama 19_Optimasi_10Tahun
A47: Ukuran | B47: Model utama + nanas | C47: Optimasi | D47: Perubahan | E47: Penjelasan | G47: ='19_Optimasi_10Tahun'!G5 -> HASIL: Untung nominal T10, tetapi NPV masih negatif pada 12%.
A48: Investasi awal T0 | B48: ='19_Optimasi_10Tahun'!B6 -> 15268150480 | C48: ='19_Optimasi_10Tahun'!C6 -> 14576030480 | D48: ='19_Optimasi_10Tahun'!D6 -> -692120000 | E48: Kas awal
A49: CAPEX 10 tahun | B49: ='19_Optimasi_10Tahun'!B7 -> 15954280480 | C49: ='19_Optimasi_10Tahun'!C7 -> 1.5050791e+10 | D49: ='19_Optimasi_10Tahun'!D7 -> -9.0348962e+08 | E49: Seluruh investasi T0–T10
A50: OPEX 10 tahun | B50: ='19_Optimasi_10Tahun'!B8 -> 4.8615696e+10 | C50: ='19_Optimasi_10Tahun'!C8 -> 4.6681381e+10 | D50: ='19_Optimasi_10Tahun'!D8 -> -1.9343152e+09 | E50: Biaya operasi setelah efisiensi
...

Sheet 02_Assumptions
A1: Pusat Penggerak dan Asumsi Model
A2: Simulasi utama cukup dengan C6 (luas kebun) dan C8 (jumlah lokasi). Harga, upah, tarif, dosis, dan produktivitas tetap dapat diedit secara opsional; populasi, volume, HOK, kru, biaya, produksi, dan arus kas dihitung otomatis.
A4: A. Proyek, finansial, dan skenario
A5: Kelompok | B5: Variabel | C5: Nilai | D5: Satuan | E5: ID sumber | F5: Tingkat keyakinan | G5: Catatan
A6: Proyek | B6: Luas bruto | C6: 100 | D6: ha | E6: USR | F6: High | G6: PENGGERAK UTAMA — ubah luas di sini
A7: Proyek | B7: Proporsi areal efektif | C7: 0.88 | D7: % bruto | E7: ASM | F7: Medium | G7: Standar desain; tidak perlu diubah untuk simulasi luas/lokasi
A8: Skenario | B8: Jumlah lokasi terpilih | C8: 1 | D8: site | E8: USR | F8: High | G8: PENGGERAK UTAMA — pilih 1 sampai 4 lokasi
A9: Tenaga kerja | B9: Hari kerja per bulan | C9: 25 | D9: hari | E9: USR | F9: High | G9: Dapat diubah menjadi 22
A10: Waktu | B10: Tahun dasar harga | C10: 2026 | D10: tahun | E10: SYS | F10: High | G10: Nominal 2026
A11: Keuangan | B11: Inflasi biaya | C11: 0.04 | D11: %/tahun | E11: ASM | F11: Medium | G11: Asumsi perencanaan; bukan forecast resmi
A12: Keuangan | B12: Eskalasi harga jual | C12: 0.03 | D12: %/tahun | E12: ASM | F12: Low | G12: Konservatif; kontrak offtake tetap diperlukan
A13: Keuangan | B13: Tingkat diskonto | C13: 0.12 | D13: % nominal | E13: ASM | F13: Medium | G13: Untuk NPV proyek tanpa utang
A14: Keuangan | B14: Cadangan CAPEX | C14: 0.1 | D14: % subtotal | E14: ASM | F14: Medium | G14: Tidak diterapkan pada akuisisi lahan
A15: Keuangan | B15: Cadangan OPEX | C15: 0.05 | D15: % subtotal | E15: ASM | F15: Medium | G15: Cadangan operasional
A16: Lahan | B16: Harga akuisisi/sewa lahan | C16: 0 | D16: Rp/ha | E16: OPEN | F16: Low | G16: Dikosongkan: wajib diisi setelah title & valuation due diligence
A17: Organik | B17: Lama fase input sintetis | C17: 2 | D17: tahun | E17: USR | F17: Medium | G17: Urea/ZA/SP-36/KCl/NPK dan pestisida sintetis berhenti setelah tahun ini
... A19: Pendapatan | B19: Premi harga organik | C19: 0 | D19: % | E19: ASM | F19: Low | G19: Tidak diasumsikan sebelum ada kontrak pembeli
A22: B. Matriks tanam agroforestri terpadu — tanpa blok komoditas
A23: Kelompok | B23: Variabel | C23: Nilai | D23: Satuan | E23: ID sumber | F23: Tingkat keyakinan | G23: Catatan
A24: Area | B24: Areal agroforestri efektif | C24: =$C$6*$C$7 -> 88 | D24: ha efektif | E24: RUMUS | F24: Tinggi | G24: Seluruh tanaman utama dan tanaman sela berada pada matriks areal yang sama
A25: Area | B25: Jalan, sempadan, sarana, dan area non-tanam | C25: =$C$6-$C$24 -> 12 | D25: ha | E25: RUMUS | F25: Tinggi | G25: Luas bruto dikurangi areal agroforestri efektif
A26: Kerapatan | B26: Kelapa genjah terpadu | C26: 83 | D26: pohon/ha efektif | E26: DES | F26: Sedang | G26: Tersebar dalam lorong mengikuti kontur dan ruang tajuk dewasa
A27: Kerapatan | B27: Durian okulasi terpadu | C27: 30 | D27: pohon/ha efektif | E27: DES | F27: Sedang | G27: Campuran varietas untuk penyerbukan dan sebaran risiko
A28: Kerapatan | B28: Pisang awal terpadu | C28: 500 | D28: rumpun/ha efektif | E28: S02 | F28: Sedang | G28: Dikurangi bertahap ketika tajuk permanen menutup
A29: Kerapatan | B29: Gamal terpadu | C29: 150 | D29: stek/ha efektif | E29: DES | F29: Sedang | G29: Pagar hidup, biomassa, dan pengikat nitrogen
A30: Kerapatan | B30: Indigofera terpadu | C30: 300 | D30: bibit/ha efektif | E30: DES | F30: Sedang | G30: Biomassa dan habitat; perlu pemangkasan
A31: Kerapatan | B31: Serai wangi terpadu | C31: 400 | D31: anakan/ha efektif | E31: DES | F31: Sedang | G31: Strip kontur dan tepi; bukan jaminan pengendalian hama
A32: Ekologi | B32: Proporsi penutup tanah hidup | C32: 0.65 | D32: % areal efektif | E32: DES | F32: Rendah | G32: Arachis, kacang tunggak, Crotalaria atau campuran setempat
A33: Ekologi | B33: Proporsi strip biodiversitas | C33: 0.02 | D33: % areal efektif | E33: DES | F33: Rendah | G33: Tanaman berbunga bertahap di lorong dan margin
A34: Pengadaan | B34: Cadangan bibit dan sulaman | C34: 0.1 | D34: % kebutuhan | E34: S13 | F34: Sedang | G34: Jumlah dibeli di atas populasi lapangan
A35: Desain | B35: Porsi lorong untuk opsi tanaman sela komersial | C35: 0.1 | D35: % areal efektif | E35: DES | F35: Rendah | G35: Nanas/komoditas tambahan hanya ditempatkan pada lorong yang cukup cahaya
A38: C. Survival, marketable yield, dan harga jual
A39: Kelompok | B39: Input | C39: Nilai | D39: Unit | E39: Source ID | F39: Confidence | G39: Catatan
A40: Survival | B40: Kelapa setelah sulaman | C40: 0.95 | D40: % | E40: ASM | F40: Medium | G40: Target sesudah gap filling tahun pertama
A41: Survival | B41: Durian setelah sulaman | C41: 0.9 | D41: % | E41: ASM | F41: Medium | G41: Drainase dan Phytophthora menentukan
A42: Survival | B42: Pisang | C42: 0.92 | D42: % | E42: ASM | F42: Medium | G42: Bibit kultur jaringan + biosecurity
A43: Packout | B43: Kelapa marketable | C43: 0.9 | D43: % | E43: ASM | F43: Low | G43: Setelah sortasi
A44: Packout | B44: Durian marketable | C44: 0.85 | D44: % | E44: ASM | F44: Low | G44: Gradeable fruit
A45: Packout | B45: Pisang marketable | C45: 0.85 | D45: % | E45: ASM | F45: Low | G45: Reject, damage, size loss
A46: Price | B46: Harga kelapa farmgate | C46: 3000 | D46: Rp/butir | E46: S04 | F46: Medium | G46: Tanpa premium kelapa aromatik
...

Sheet 03_Land_Screening
A1: Seleksi Lahan dan Gerbang Kesiapan
A2: Digunakan sebelum pembukaan lahan untuk membandingkan calon lokasi berdasarkan bukti legal, sosial, lingkungan, tanah, air, akses, penyakit, dan pasar. Gerbang Tidak Layak selalu mengesampingkan skor total yang terlihat menarik.
A4: A. Skor seleksi berbobot
A5: Kriteria | B5: Bobot | C5: Minimum | D5: Bukti wajib | E5: Calon A | F5: Calon B | G5: Calon C | H5: Calon D | I5: Penanggung jawab | J5: Waktu | K5: Hubungan tidak layak
A6: Legal title, overlap, land-use conformity | B6: 0.2 | C6: 4 | D6: Certificates, spatial plan, dispute/community check | I6: Legal | J6: W1-2 | K6: Any unresolved conflict = No-Go
A7: E&S, protected area, HCV/forest status | B7: 0.15 | C7: 4 | D7: Official maps + field HCV/social verification | I7: ESG | J7: W1-3 | K7: Natural forest/protected/HCV clearing = No-Go
A8: Soil depth, texture, pH, CEC, organic C | B8: 0.15 | C8: 3 | D8: 40+ composite samples, pits, laboratory | I8: Agronomist | J8: W2-3 | K8: Severe rooting constraint may be No-Go
A9: Drainage, flood, water table | B9: 0.1 | C9: 4 | D9: Topography, pits, flood history, hydrology | I9: Engineer | J9: W2-3 | K9: Chronic flood/waterlogging = No-Go
A10: Dry-season water reliability | B10: 0.1 | C10: 4 | D10: Source yield, rights, dry-season test, water quality | I10: Engineer | J10: W2-3 | K10: No reliable establishment water = No-Go
A11: Slope, erosion, mechanization | B11: 0.08 | C11: 3 | D11: DEM/topo, slope classes, access | I11: GIS/Engineer | J11: W2-3 | K11: >25% on material area = reject/very limited
A12: Banana disease history/biosecurity | B12: 0.07 | C12: 4 | D12: Fusarium/blood disease history, soil movement risk | I12: Plant Health | J12: W2-3 | K12: Known severe history without isolation = No-Go
A13: Access, power, labor, logistics | B13: 0.06 | C13: 3 | D13: Road seasonality, distance, labor survey | I13: Ops | J13: W1-3 | K13: May materially change CAPEX/OPEX
A14: Market/offtake and postharvest route | B14: 0.05 | C14: 3 | D14: Buyer interviews, grades, transport loss | I14: Commercial | J14: W2-4 | K14: Low score requires contracted solution
A15: Contiguity/expansion and security | B15: 0.04 | C15: 3 | D15: Boundary survey, neighboring uses, theft/fire risk | I15: Ops | J15: W1-3 | K15: Split sites duplicate cost
A16: Skor kesiapan berbobot | E16: =IF(COUNT(E6:E15)=10,SUMPRODUCT($B$6:$B$15,E6:E15)/5,"Input scores") -> Input scores | F16: =IF(COUNT(F6:F15)=10,SUMPRODUCT($B$6:$B$15,F6:F15)/5,"Input scores") -> Input scores | G16: =IF(COUNT(G6:G15)=10,SUMPRODUCT($B$6:$B$15,G6:G15)/5,"Input scores") -> Input scores | H16: =IF(COUNT(H6:H15)=10,SUMPRODUCT($B$6:$B$15,H6:H15)/5,"Input scores") -> Input scores
A19: B. Gerbang Tidak Layak yang wajib
A20: Gerbang | B20: Tolak/hentikan jika | C20: Bukti | D20: Mitigasi diperbolehkan? | E20: Pemilik keputusan | F20: Sebelum biaya | G20: Status | H20: Catatan
A21: Tenure | B21: Unresolved ownership, overlap, encumbrance, community conflict | C21: Legal report + consultation | D21: No, resolve first | E21: Investment committee | F21: Before survey | G21: OPEN
A22: Forest/HCV | B22: Natural forest, protected area, critical habitat conversion | C22: Official + HCV assessment | D22: No clearing | E22: Board/ESG | F22: Before clearing | G22: OPEN
A23: Flood/drainage | B23: Chronic flood or water table incompatible with durian/banana | C23: Hydrology/topo | D23: Only if engineered and economic | E23: Agronomist/engineer | F23: Before design | G23: OPEN
A24: Water | B24: No legal/reliable dry-season source | C24: Yield/quality/right test | D24: Alternative source must be proven | E24: Ops | F24: Before planting | G24: OPEN
A25: Banana disease | B25: Severe Fusarium/blood disease history with uncontrollable pathways | C25: Plant health survey | D25: Quarantine block only if approved | E25: Plant health lead | F25: Before banana procurement | G25: OPEN
A26: Slope/erosion | B26: Material planting area >25% slope/unstable | C26: Topographic/geotech | D26: Exclude area or reject | E26: Engineer | F26: Before clearing | G26: OPEN
A29: C. Proses keputusan lahan empat minggu
A30: Minggu | B30: Aktivitas | C30: Keluaran | D30: Orang | E30: Durasi | F30: Tautan anggaran | G30: Keputusan
A31: 1 | B31: Desktop shortlist + legal data room | C31: 2-4 candidates, document gaps | D31: 4 | E31: 5 days | F31: CAPEX Assessment | G31: Shortlist
A32: 2 | B32: Reconnaissance, community, drone/boundary | C32: Orthomosaic, access, red flags | D32: 8 | E32: 5-7 days | F32: CAPEX Survey | G32: Drop clear No-Go
A33: 3 | B33: Soil, pits, infiltration, water, HCV | C33: Lab samples and field evidence | D33: 10 | E33: 5-7 days | F33: CAPEX Survey | G33: Conditional Go
A34: 4 | B34: Scoring, master concept, vendor BOQ | C34: Go/No-Go memo + negotiation cap | D34: 6 | E34: 5 days | F34: CAPEX Design | G34: Investment decision

Sheet 04_Planting_Design
A1: Desain Populasi dan Pengadaan Bibit
A2: Luas efektif dan standar kerapatan otomatis menjadi populasi, bibit, tanaman hidup, serta biaya. Untuk simulasi luas/lokasi, jangan ketik ulang angka pada sheet ini.
A4: A. Populasi lapangan dalam matriks terpadu
A5: Lapisan/area | B5: Area (ha) | C5: Kelapa/ha | D5: Kelapa | E5: Durian/ha | F5: Durian | G5: Pisang/ha | H5: Pisang | I5: Gamal | J5: Indigofera | K5: Serai wangi | L5: Nanas | M5: Penutup tanah (ha) | N5: Keterangan | O5: Aktif
A6: Agroforestri terpadu | B6: ='02_Assumptions'!$C$24 -> 88 | C6: ='02_Assumptions'!$C$26 -> 83 | D6: =$B6*$C6*'02_Assumptions'!$C$150 -> 7304 | E6: ='02_Assumptions'!$C$27 -> 30 | F6: =$B6*$E6*'02_Assumptions'!$C$151 -> 2640 | G6: ='02_Assumptions'!$C$28 -> 500 | H6: =$B6*$G6*'02_Assumptions'!$C$152 -> 44000 | I6: =$B6*'02_Assumptions'!$C$29*'02_Assumptions'!$C$153 -> 13200 | J6: =$B6*'02_Assumptions'!$C$30*'02_Assumptions'!$C$154 -> 26400 | K6: =$B6*'02_Assumptions'!$C$31*'02_Assumptions'!$C$155 -> 35200 | L6: ='17_Model_Fleksibel'!$E$6 -> 220000 | M6: ='17_Model_Fleksibel'!$E$7 -> 57.2 | N6: Semua komoditas berada pada areal yang sama | O6: 1
A7: Area non-tanam | B7: ='02_Assumptions'!$C$25 -> 12 | C7: 0 | D7: 0 | E7: 0 | F7: 0 | G7: 0 | H7: 0 | I7: 0 | J7: 0 | K7: 0 | L7: 0 | M7: 0 | N7: Jalan, sempadan, sarana, dan area lindung | O7: 0
A8: TOTAL | B8: =SUM(B6:B7) -> 100 | D8: =SUM(D6:D7) -> 7304 | F8: =SUM(F6:F7) -> 2640 | H8: =SUM(H6:H7) -> 44000 | I8: =SUM(I6:I7) -> 13200 | J8: =SUM(J6:J7) -> 26400 | K8: =SUM(K6:K7) -> 35200 | L8: =SUM(L6:L7) -> 220000 | M8: =SUM(M6:M7) -> 57.2
A11: B. Pengadaan bibit termasuk cadangan sulaman
A12: Bibit | B12: Kebutuhan lapangan | C12: Cadangan | D12: Jumlah dibeli | E12: Satuan | F12: Harga/satuan | G12: Total | H12: Catatan
A13: Kelapa genjah | B13: =$D$8 -> 7304 | C13: ='02_Assumptions'!$C$34 -> 0.1 | D13: =$B13*(1+$C13) -> 8034.4 | E13: bibit | F13: ='02_Assumptions'!$C$53 -> 65000 | G13: =$D13*$F13 -> 5.22236e+08 | H13: Varietas bersertifikat dan sesuai elevasi serta pasar
A14: Durian okulasi | B14: =$F$8 -> 2640 | C14: ='02_Assumptions'!$C$34 -> 0.1 | D14: =$B14*(1+$C14) -> 2904 | E14: bibit | F14: ='02_Assumptions'!$C$54 -> 75000 | G14: =$D14*$F14 -> 2.178e+08 | H14: Campuran varietas untuk penyerbukan dan sebaran risiko
A15: Pisang kultur jaringan | B15: =$H$8 -> 44000 | C15: ='02_Assumptions'!$C$34 -> 0.1 | D15: =$B15*(1+$C15) -> 48400 | E15: bibit | F15: ='02_Assumptions'!$C$55 -> 15000 | G15: =$D15*$F15 -> 7.26e+08 | H15: Karantina batch dan aklimatisasi
A16: Gamal | B16: =$I$8 -> 13200 | C16: ='02_Assumptions'!$C$34 -> 0.1 | D16: =$B16*(1+$C16) -> 14520 | E16: stek | F16: ='02_Assumptions'!$C$56 -> 2500 | G16: =$D16*$F16 -> 36300000 | H16: Pagar hidup dan biomassa
A17: Indigofera | B17: =$J$8 -> 26400 | C17: ='02_Assumptions'!$C$34 -> 0.1 | D17: =$B17*(1+$C17) -> 29040 | E17: bibit | F17: ='02_Assumptions'!$C$57 -> 3000 | G17: =$D17*$F17 -> 87120000 | H17: Dipangkas agar tidak menaungi
A18: Serai wangi | B18: =$K$8 -> 35200 | C18: ='02_Assumptions'!$C$34 -> 0.1 | D18: =$B18*(1+$C18) -> 38720 | E18: anakan | F18: ='02_Assumptions'!$C$58 -> 1500 | G18: =$D18*$F18 -> 58080000 | H18: Strip kontur dan batas
A19: TOTAL PENGADAAN BIBIT TERMASUK OPSI | G19: =SUM(G13:G18)+'17_Model_Fleksibel'!$I$18 -> 2.151776e+09
A22: C. Populasi hidup untuk model hasil
A23: Komoditas | B23: Populasi lapangan | C23: Survival | D23: Tanaman hidup
A24: Kelapa | B24: =D8 -> 7304 | C24: ='02_Assumptions'!$C$40 -> 0.95 | D24: =B24*C24 -> 6938.8
A25: Durian | B25: =F8 -> 2640 | C25: ='02_Assumptions'!$C$41 -> 0.9 | D25: =B25*C25 -> 2376
A26: Pisang | B26: =H8 -> 44000 | C26: ='02_Assumptions'!$C$42 -> 0.92 | D26: =B26*C26 -> 40480
A29: D. Fungsi tanaman pendukung dan aturan desain
A30: Tanaman/elemen | B30: Fungsi | C30: Posisi | D30: Pengelolaan | E30: Risiko | F30: Pendapatan dasar | G30: Keputusan | H30: Catatan
A31: Gamal (Gliricidia) | B31: Pengikat N, pagar hidup, biomassa | C31: Lorong, kontur, dan batas | D31: Pangkas 3–4 kali/tahun | E31: Kompetisi cahaya/akar | F31: 0 | G31: Masuk | H31: Tidak dianggap sebagai pestisida
A32: Indigofera | B32: Pengikat N, biomassa, habitat | C32: Lorong tersebar | D32: Pangkas dan benamkan biomassa | E32: Dapat menjadi semak | F32: 0 | G32: Masuk | H32: Potensi pakan bila ada ternak
A33: Serai wangi | B33: Strip aromatik dan pengendali erosi | C33: Tepi drainase dan kontur | D33: Panen/pangkas berkala | E33: Tidak menjamin hama hilang | F33: 0 | G33: Masuk | H33: Pendapatan nol tanpa penyulingan/offtake
A34: Arachis/kacang tunggak/Crotalaria | B34: Penutup tanah, N, pengendali erosi | C34: Lorong terbuka | D34: Rotasi; cegah lilitan pada pohon | E34: Rodensia/kompetisi | F34: 0 | G34: Masuk | H34: Campuran spesifik lokasi
A35: Strip tanaman berbunga | B35: Habitat musuh alami | C35: 1–2% margin dan lorong | D35: Penaburan bertahap | E35: Dapat menjadi inang hama | F35: 0 | G35: Masuk | H35: Pilih jenis setempat
A36: Sempadan riparian/HCV | B36: Perlindungan air dan biodiversitas | C36: Area non-tanam | D36: Tandai, pantau, tanpa pembukaan | E36: Mengurangi areal efektif | F36: 0 | G36: Wajib | H36: Termasuk dalam area non-tanam

Sheet 05_Workplan_Labor
A1: Rencana Kerja, HOK, Durasi, dan Kebutuhan Kru
A2: HOK, durasi, biaya tenaga kerja, kru rata-rata, dan kru puncak dihitung otomatis dari luas dan jumlah lokasi. Upah tetap dapat diedit pada 02_Assumptions.
A4: A. Pekerjaan Tahun 0: dari uji tuntas sampai pembentukan tanaman
A5: Tahap | B5: Aktivitas | C5: Mulai | D5: Selesai | E5: Basis | F5: Jumlah 1 lokasi | G5: Jumlah 4 lokasi | H5: HOK/unit | I5: HOK 1 lokasi | J5: HOK 4 lokasi | K5: Biaya langsung 1 lokasi | L5: Biaya langsung 4 lokasi | M5: Peralatan/catatan | N5: M1 | O5: M2 | P5: M3 | Q5: M4 | R5: M5 | S5: M6 | T5: M7 | U5: M8 | V5: M9 | W5: M10 | X5: M11 | Y5: M12 | Z5: Crew selected
A6: Assessment | B6: Desktop shortlist & GIS | C6: 1 | D6: 1 | E6: lot | F6: 1 | G6: 1 | H6: 30 | I6: =F6*H6 -> 30 | J6: =G6*H6 -> 30 | K6: =0 -> 0 | L6: =0 -> 0 | M6: Professional service | N6: =IF(AND(1>=$C6,1<=$D6),($I6+($J6-$I6)*('02_Assumptions'!$C$8-1)/3)/($D6-$C6+1),0) -> 30 | O6: =IF(AND(2>=$C6,2<=$D6),($I6+($J6-$I6)*('02_Assumptions'!$C$8-1)/3)/($D6-$C6+1),0) -> 0 | P6: =IF(AND(3>=$C6,3<=$D6),($I6+($J6-$I6)*('02_Assumptions'!$C$8-1)/3)/($D6-$C6+1),0) -> 0 | Q6: =IF(AND(4>=$C6,4<=$D6),($I6+($J6-$I6)*('02_Assumptions'!$C$8-1)/3)/($D6-$C6+1),0) -> 0 | R6: =IF(AND(5>=$C6,5<=$D6),($I6+($J6-$I6)*('02_Assumptions'!$C$8-1)/3)/($D6-$C6+1),0) -> 0 | S6: =IF(AND(6>=$C6,6<=$D6),($I6+($J6-$I6)*('02_Assumptions'!$C$8-1)/3)/($D6-$C6+1),0) -> 0 | T6: =IF(AND(7>=$C6,7<=$D6),($I6+($J6-$I6)*('02_Assumptions'!$C$8-1)/3)/($D6-$C6+1),0) -> 0 | U6: =IF(AND(8>=$C6,8<=$D6),($I6+($J6-$I6)*('02_Assumptions'!$C$8-1)/3)/($D6-$C6+1),0) -> 0 | V6: =IF(AND(9>=$C6,9<=$D6),($I6+($J6-$I6)*('02_Assumptions'!$C$8-1)/3)/($D6-$C6+1),0) -> 0 | W6: =IF(AND(10>=$C6,10<=$D6),($I6+($J6-$I6)*('02_Assumptions'!$C$8-1)/3)/($D6-$C6+1),0) -> 0 | X6: =IF(AND(11>=$C6,11<=$D6),($I6+($J6-$I6)*('02_Assumptions'!$C$8-1)/3)/($D6-$C6+1),0) -> 0 | Y6: =IF(AND(12>=$C6,12<=$D6),($I6+($J6-$I6)*('02_Assumptions'!$C$8-1)/3)/($D6-$C6+1),0) -> 0 | Z6: =(I6+(J6-I6)*('02_Assumptions'!$C$8-1)/3)/(D6-C6+1)/'02_Assumptions'!$C$9 -> 1.2
A7: Assessment | B7: Legal/tenure due diligence | C7: 1 | D7: 2 | E7: site | F7: 1 | G7: 4 | H7: 40 | I7: =F7*H7 -> 40 | J7: =G7*H7 -> 160 | K7: =0 -> 0 | L7: =0 -> 0 | M7: Legal fee in CAPEX | N7: =IF(AND(1>=$C7,1<=$D7),($I7+($J7-$I7)*('02_Assumptions'!$C$8-1)/3)/($D7-$C7+1),0) -> 20 | O7: =IF(AND(2>=$C7,2<=$D7),($I7+($J7-$I7)*('02_Assumptions'!$C$8-1)/3)/($D7-$C7+1),0) -> 20 | P7: =IF(AND(3>=$C7,3<=$D7),($I7+($J7-$I7)*('02_Assumptions'!$C$8-1)/3)/($D7-$C7+1),0) -> 0 | Q7: =IF(AND(4>=$C7,4<=$D7),($I7+($J7-$I7)*('02_Assumptions'!$C$8-1)/3)/($D7-$C7+1),0) -> 0 | R7: =IF(AND(5>=$C7,5<=$D7),($I7+($J7-$I7)*('02_Assumptions'!$C$8-1)/3)/($D7-$C7+1),0) -> 0 | S7: =IF(AND(6>=$C7,6<=$D7),($I7+($J7-$I7)*('02_Assumptions'!$C$8-1)/3)/($D7-$C7+1),0) -> 0 | T7: =IF(AND(7>=$C7,7<=$D7),($I7+($J7-$I7)*('02_Assumptions'!$C$8-1)/3)/($D7-$C7+1),0) -> 0 | U7: =IF(AND(8>=$C7,8<=$D7),($I7+($J7-$I7)*('02_Assumptions'!$C$8-1)/3)/($D7-$C7+1),0) -> 0 | V7: =IF(AND(9>=$C7,9<=$D7),($I7+($J7-$I7)*('02_Assumptions'!$C$8-1)/3)/($D7-$C7+1),0) -> 0 | W7: =IF(AND(10>=$C7,10<=$D7),($I7+($J7-$I7)*('02_Assumptions'!$C$8-1)/3)/($D7-$C7+1),0) -> 0 | X7: =IF(AND(11>=$C7,11<=$D7),($I7+($J7-$I7)*('02_Assumptions'!$C$8-1)/3)/($D7-$C7+1),0) -> 0 | Y7: =IF(AND(12>=$C7,12<=$D7),($I7+($J7-$I7)*('02_Assumptions'!$C$8-1)/3)/($D7-$C7+1),0) -> 0 | Z7: =(I7+(J7-I7)*('02_Assumptions'!$C$8-1)/3)/(D7-C7+1)/'02_Assumptions'!$C$9 -> 0.8
A8: Assessment | B8: Reconnaissance & community check | C8: 1 | D8: 2 | E8: site | F8: 1 | G8: 4 | H8: 30 | I8: =F8*H8 -> 30 | J8: =G8*H8 -> 120 | K8: =0 -> 0 | L8: =0 -> 0 | M8: Travel package in CAPEX | N8: =IF(AND(1>=$C8,1<=$D8),($I8+($J8-$I8)*('02_Assumptions'!$C$8-1)/3)/($D8-$C8+1),0) -> 15 | O8: =IF(AND(2>=$C8,2<=$D8),($I8+($J8-$I8)*('02_Assumptions'!$C$8-1)/3)/($D8-$C8+1),0) -> 15 | P8: =IF(AND(3>=$C8,3<=$D8),($I8+($J8-$I8)*('02_Assumptions'!$C$8-1)/3)/($D8-$C8+1),0) -> 0 | Q8: =IF(AND(4>=$C8,4<=$D8),($I8+($J8-$I8)*('02_Assumptions'!$C$8-1)/3)/($D8-$C8+1),0) -> 0 | R8: =IF(AND(5>=$C8,5<=$D8),($I8+($J8-$I8)*('02_Assumptions'!$C$8-1)/3)/($D8-$C8+1),0) -> 0 | S8: =IF(AND(6>=$C8,6<=$D8),($I8+($J8-$I8)*('02_Assumptions'!$C$8-1)/3)/($D8-$C8+1),0) -> 0 | T8: =IF(AND(7>=$C8,7<=$D8),($I8+($J8-$I8)*('02_Assumptions'!$C$8-1)/3)/($D8-$C8+1),0) -> 0 | U8: =IF(AND(8>=$C8,8<=$D8),($I8+($J8-$I8)*('02_Assumptions'!$C$8-1)/3)/($D8-$C8+1),0) -> 0 | V8: =IF(AND(9>=$C8,9<=$D8),($I8+($J8-$I8)*('02_Assumptions'!$C$8-1)/3)/($D8-$C8+1),0) -> 0 | W8: =IF(AND(10>=$C8,10<=$D8),($I8+($J8-$I8)*('02_Assumptions'!$C$8-1)/3)/($D8-$C8+1),0) -> 0 | X8: =IF(AND(11>=$C8,11<=$D8),($I8+($J8-$I8)*('02_Assumptions'!$C$8-1)/3)/($D8-$C8+1),0) -> 0 | Y8: =IF(AND(12>=$C8,12<=$D8),($I8+($J8-$I8)*('02_Assumptions'!$C$8-1)/3)/($D8-$C8+1),0) -> 0 | Z8: =(I8+(J8-I8)*('02_Assumptions'!$C$8-1)/3)/(D8-C8+1)/'02_Assumptions'!$C$9 -> 0.6
A9: Survey | B9: Drone/boundary/topo survey | C9: 2 | D9: 3 | E9: ha | F9: ='02_Assumptions'!$C$6 -> 100 | G9: ='02_Assumptions'!$C$6 -> 100 | H9: 0.2 | I9: =F9*H9 -> 20 | J9: =G9*H9 -> 20 | K9: =0 -> 0 | L9: =0 -> 0 | M9: Professional service | N9: =IF(AND(1>=$C9,1<=$D9),($I9+($J9-$I9)*('02_Assumptions'!$C$8-1)/3)/($D9-$C9+1),0) -> 0 | O9: =IF(AND(2>=$C9,2<=$D9),($I9+($J9-$I9)*('02_Assumptions'!$C$8-1)/3)/($D9-$C9+1),0) -> 10 | P9: =IF(AND(3>=$C9,3<=$D9),($I9+($J9-$I9)*('02_Assumptions'!$C$8-1)/3)/($D9-$C9+1),0) -> 10 | Q9: =IF(AND(4>=$C9,4<=$D9),($I9+($J9-$I9)*('02_Assumptions'!$C$8-1)/3)/($D9-$C9+1),0) -> 0 | R9: =IF(AND(5>=$C9,5<=$D9),($I9+($J9-$I9)*('02_Assumptions'!$C$8-1)/3)/($D9-$C9+1),0) -> 0 | S9: =IF(AND(6>=$C9,6<=$D9),($I9+($J9-$I9)*('02_Assumptions'!$C$8-1)/3)/($D9-$C9+1),0) -> 0 | T9: =IF(AND(7>=$C9,7<=$D9),($I9+($J9-$I9)*('02_Assumptions'!$C$8-1)/3)/($D9-$C9+1),0) -> 0 | U9: =IF(AND(8>=$C9,8<=$D9),($I9+($J9-$I9)*('02_Assumptions'!$C$8-1)/3)/($D9-$C9+1),0) -> 0 | V9: =IF(AND(9>=$C9,9<=$D9),($I9+($J9-$I9)*('02_Assumptions'!$C$8-1)/3)/($D9-$C9+1),0) -> 0 | W9: =IF(AND(10>=$C9,10<=$D9),($I9+($J9-$I9)*('02_Assumptions'!$C$8-1)/3)/($D9-$C9+1),0) -> 0 | X9: =IF(AND(11>=$C9,11<=$D9),($I9+($J9-$I9)*('02_Assumptions'!$C$8-1)/3)/($D9-$C9+1),0) -> 0 | Y9: =IF(AND(12>=$C9,12<=$D9),($I9+($J9-$I9)*('02_Assumptions'!$C$8-1)/3)/($D9-$C9+1),0) -> 0 | Z9: =(I9+(J9-I9)*('02_Assumptions'!$C$8-1)/3)/(D9-C9+1)/'02_Assumptions'!$C$9 -> 0.4
A10: Survey | B10: Soil composite sampling | C10: 2 | D10: 3 | E10: sample | F10: ='02_Assumptions'!$C$6/'02_Assumptions'!$C$96 -> 40 | G10: ='02_Assumptions'!$C$6/'02_Assumptions'!$C$96+12 -> 52 | H10: 1 | I10: =F10*H10 -> 40 | J10: =G10*H10 -> 52 | K10: =0 -> 0 | L10: =0 -> 0 | M10: Lab/survey package | N10: =IF(AND(1>=$C10,1<=$D10),($I10+($J10-$I10)*('02_Assumptions'!$C$8-1)/3)/($D10-$C10+1),0) -> 0 | O10: =IF(AND(2>=$C10,2<=$D10),($I10+($J10-$I10)*('02_Assumptions'!$C$8-1)/3)/($D10-$C10+1),0) -> 20 | P10: =IF(AND(3>=$C10,3<=$D10),($I10+($J10-$I10)*('02_Assumptions'!$C$8-1)/3)/($D10-$C10+1),0) -> 20 | Q10: =IF(AND(4>=$C10,4<=$D10),($I10+($J10-$I10)*('02_Assumptions'!$C$8-1)/3)/($D10-$C10+1),0) -> 0 | R10: =IF(AND(5>=$C10,5<=$D10),($I10+($J10-$I10)*('02_Assumptions'!$C$8-1)/3)/($D10-$C10+1),0) -> 0 | S10: =IF(AND(6>=$C10,6<=$D10),($I10+($J10-$I10)*('02_Assumptions'!$C$8-1)/3)/($D10-$C10+1),0) -> 0 | T10: =IF(AND(7>=$C10,7<=$D10),($I10+($J10-$I10)*('02_Assumptions'!$C$8-1)/3)/($D10-$C10+1),0) -> 0 | U10: =IF(AND(8>=$C10,8<=$D10),($I10+($J10-$I10)*('02_Assumptions'!$C$8-1)/3)/($D10-$C10+1),0) -> 0 | V10: =IF(AND(9>=$C10,9<=$D10),($I10+($J10-$I10)*('02_Assumptions'!$C$8-1)/3)/($D10-$C10+1),0) -> 0 | W10: =IF(AND(10>=$C10,10<=$D10),($I10+($J10-$I10)*('02_Assumptions'!$C$8-1)/3)/($D10-$C10+1),0) -> 0 | X10: =IF(AND(11>=$C10,11<=$D10),($I10+($J10-$I10)*('02_Assumptions'!$C$8-1)/3)/($D10-$C10+1),0) -> 0 | Y10: =IF(AND(12>=$C10,12<=$D10),($I10+($J10-$I10)*('02_Assumptions'!$C$8-1)/3)/($D10-$C10+1),0) -> 0 | Z10: =(I10+(J10-I10)*('02_Assumptions'!$C$8-1)/3)/(D10-C10+1)/'02_Assumptions'!$C$9 -> 0.8
A11: Safeguard | B11: E&S/HCV baseline | C11: 2 | D11: 3 | E11: site | F11: 1 | G11: 4 | H11: 60 | I11: =F11*H11 -> 60 | J11: =G11*H11 -> 240 | K11: =0 -> 0 | L11: =0 -> 0 | M11: Consultant package | N11: =IF(AND(1>=$C11,1<=$D11),($I11+($J11-$I11)*('02_Assumptions'!$C$8-1)/3)/($D11-$C11+1),0) -> 0 | O11: =IF(AND(2>=$C11,2<=$D11),($I11+($J11-$I11)*('02_Assumptions'!$C$8-1)/3)/($D11-$C11+1),0) -> 30 | P11: =IF(AND(3>=$C11,3<=$D11),($I11+($J11-$I11)*('02_Assumptions'!$C$8-1)/3)/($D11-$C11+1),0) -> 30 | Q11: =IF(AND(4>=$C11,4<=$D11),($I11+($J11-$I11)*('02_Assumptions'!$C$8-1)/3)/($D11-$C11+1),0) -> 0 | R11: =IF(AND(5>=$C11,5<=$D11),($I11+($J11-$I11)*('02_Assumptions'!$C$8-1)/3)/($D11-$C11+1),0) -> 0 | S11: =IF(AND(6>=$C11,6<=$D11),($I11+($J11-$I11)*('02_Assumptions'!$C$8-1)/3)/($D11-$C11+1),0) -> 0 | T11: =IF(AND(7>=$C11,7<=$D11),($I11+($J11-$I11)*('02_Assumptions'!$C$8-1)/3)/($D11-$C11+1),0) -> 0 | U11: =IF(AND(8>=$C11,8<=$D11),($I11+($J11-$I11)*('02_Assumptions'!$C$8-1)/3)/($D11-$C11+1),0) -> 0 | V11: =IF(AND(9>=$C11,9<=$D11),($I11+($J11-$I11)*('02_Assumptions'!$C$8-1)/3)/($D11-$C11+1),0) -> 0 | W11: =IF(AND(10>=$C11,10<=$D11),($I11+($J11-$I11)*('02_Assumptions'!$C$8-1)/3)/($D11-$C11+1),0) -> 0 | X11: =IF(AND(11>=$C11,11<=$D11),($I11+($J11-$I11)*('02_Assumptions'!$C$8-1)/3)/($D11-$C11+1),0) -> 0 | Y11: =IF(AND(12>=$C11,12<=$D11),($I11+($J11-$I11)*('02_Assumptions'!$C$8-1)/3)/($D11-$C11+1),0) -> 0 | Z11: =(I11+(J11-I11)*('02_Assumptions'!$C$8-1)/3)/(D11-C11+1)/'02_Assumptions'!$C$9 -> 1.2
A12: Land prep | B12: HCV marking & exclusion | C12: 3 | D12: 4 | E12: ha | F12: ='02_Assumptions'!$C$6 -> 100 | G12: ='02_Assumptions'!$C$6 -> 100 | H12: 2 | I12: =F12*H12 -> 200 | J12: =G12*H12 -> 200 | K12: =I12*'02_Assumptions'!$C$60 -> 24000000 | L12: =J12*'02_Assumptions'!$C$60 -> 24000000 | M12: Direct field crew | N12: =IF(AND(1>=$C12,1<=$D12),($I12+($J12-$I12)*('02_Assumptions'!$C$8-1)/3)/($D12-$C12+1),0) -> 0 | O12: =IF(AND(2>=$C12,2<=$D12),($I12+($J12-$I12)*('02_Assumptions'!$C$8-1)/3)/($D12-$C12+1),0) -> 0 | P12: =IF(AND(3>=$C12,3<=$D12),($I12+($J12-$I12)*('02_Assumptions'!$C$8-1)/3)/($D12-$C12+1),0) -> 100 | Q12: =IF(AND(4>=$C12,4<=$D12),($I12+($J12-$I12)*('02_Assumptions'!$C$8-1)/3)/($D12-$C12+1),0) -> 100 | R12: =IF(AND(5>=$C12,5<=$D12),($I12+($J12-$I12)*('02_Assumptions'!$C$8-1)/3)/($D12-$C12+1),0) -> 0 | S12: =IF(AND(6>=$C12,6<=$D12),($I12+($J12-$I12)*('02_Assumptions'!$C$8-1)/3)/($D12-$C12+1),0) -> 0 | T12: =IF(AND(7>=$C12,7<=$D12),($I12+($J12-$I12)*('02_Assumptions'!$C$8-1)/3)/($D12-$C12+1),0) -> 0 | U12: =IF(AND(8>=$C12,8<=$D12),($I12+($J12-$I12)*('02_Assumptions'!$C$8-1)/3)/($D12-$C12+1),0) -> 0 | V12: =IF(AND(9>=$C12,9<=$D12),($I12+($J12-$I12)*('02_Assumptions'!$C$8-1)/3)/($D12-$C12+1),0) -> 0 | W12: =IF(AND(10>=$C12,10<=$D12),($I12+($J12-$I12)*('02_Assumptions'!$C$8-1)/3)/($D12-$C12+1),0) -> 0 | X12: =IF(AND(11>=$C12,11<=$D12),($I12+($J12-$I12)*('02_Assumptions'!$C$8-1)/3)/($D12-$C12+1),0) -> 0 | Y12: =IF(AND(12>=$C12,12<=$D12),($I12+($J12-$I12)*('02_Assumptions'!$C$8-1)/3)/($D12-$C12+1),0) -> 0 | Z12: =(I12+(J12-I12)*('02_Assumptions'!$C$8-1)/3)/(D12-C12+1)/'02_Assumptions'!$C$9 -> 4
A13: Land prep | B13: Selective zero-burn clearing | C13: 4 | D13: 6 | E13: ha | F13: ='02_Assumptions'!$C$6 -> 100 | G13: ='02_Assumptions'!$C$6 -> 100 | H13: 18 | I13: =F13*H13 -> 1800 | J13: =G13*H13 -> 1800 | K13: =I13*'02_Assumptions'!$C$60 -> 216000000 | L13: =J13*'02_Assumptions'!$C$60 -> 216000000 | M13: Manual crew; machines contracted separately | N13: =IF(AND(1>=$C13,1<=$D13),($I13+($J13-$I13)*('02_Assumptions'!$C$8-1)/3)/($D13-$C13+1),0) -> 0 | O13: =IF(AND(2>=$C13,2<=$D13),($I13+($J13-$I13)*('02_Assumptions'!$C$8-1)/3)/($D13-$C13+1),0) -> 0 | P13: =IF(AND(3>=$C13,3<=$D13),($I13+($J13-$I13)*('02_Assumptions'!$C$8-1)/3)/($D13-$C13+1),0) -> 0 | Q13: =IF(AND(4>=$C13,4<=$D13),($I13+($J13-$I13)*('02_Assumptions'!$C$8-1)/3)/($D13-$C13+1),0) -> 600 | R13: =IF(AND(5>=$C13,5<=$D13),($I13+($J13-$I13)*('02_Assumptions'!$C$8-1)/3)/($D13-$C13+1),0) -> 600 | S13: =IF(AND(6>=$C13,6<=$D13),($I13+($J13-$I13)*('02_Assumptions'!$C$8-1)/3)/($D13-$C13+1),0) -> 600 | T13: =IF(AND(7>=$C13,7<=$D13),($I13+($J13-$I13)*('02_Assumptions'!$C$8-1)/3)/($D13-$C13+1),0) -> 0 | U13: =IF(AND(8>=$C13,8<=$D13),($I13+($J13-$I13)*('02_Assumptions'!$C$8-1)/3)/($D13-$C13+1),0) -> 0 | V13: =IF(AND(9>=$C13,9<=$D13),($I13+($J13-$I13)*('02_Assumptions'!$C$8-1)/3)/($D13-$C13+1),0) -> 0 | W13: =IF(AND(10>=$C13,10<=$D13),($I13+($J13-$I13)*('02_Assumptions'!$C$8-1)/3)/($D13-$C13+1),0) -> 0 | X13: =IF(AND(11>=$C13,11<=$D13),($I13+($J13-$I13)*('02_Assumptions'!$C$8-1)/3)/($D13-$C13+1),0) -> 0 | Y13: =IF(AND(12>=$C13,12<=$D13),($I13+($J13-$I13)*('02_Assumptions'!$C$8-1)/3)/($D13-$C13+1),0) -> 0 | Z13: =(I13+(J13-I13)*('02_Assumptions'!$C$8-1)/3)/(D13-C13+1)/'02_Assumptions'!$C$9 -> 24
A14: Land prep | B14: Biomass chipping/stacking/mulch | C14: 4 | D14: 7 | E14: ha | F14: ='02_Assumptions'!$C$6 -> 100 | G14: ='02_Assumptions'!$C$6 -> 100 | H14: 8 | I14: =F14*H14 -> 800 | J14: =G14*H14 -> 800 | K14: =I14*'02_Assumptions'!$C$60 -> 96000000 | L14: =J14*'02_Assumptions'!$C$60 -> 96000000 | M14: No burning | N14: =IF(AND(1>=$C14,1<=$D14),($I14+($J14-$I14)*('02_Assumptions'!$C$8-1)/3)/($D14-$C14+1),0) -> 0 | O14: =IF(AND(2>=$C14,2<=$D14),($I14+($J14-$I14)*('02_Assumptions'!$C$8-1)/3)/($D14-$C14+1),0) -> 0 | P14: =IF(AND(3>=$C14,3<=$D14),($I14+($J14-$I14)*('02_Assumptions'!$C$8-1)/3)/($D14-$C14+1),0) -> 0 | Q14: =IF(AND(4>=$C14,4<=$D14),($I14+($J14-$I14)*('02_Assumptions'!$C$8-1)/3)/($D14-$C14+1),0) -> 200 | R14: =IF(AND(5>=$C14,5<=$D14),($I14+($J14-$I14)*('02_Assumptions'!$C$8-1)/3)/($D14-$C14+1),0) -> 200 | S14: =IF(AND(6>=$C14,6<=$D14),($I14+($J14-$I14)*('02_Assumptions'!$C$8-1)/3)/($D14-$C14+1),0) -> 200 | T14: =IF(AND(7>=$C14,7<=$D14),($I14+($J14-$I14)*('02_Assumptions'!$C$8-1)/3)/($D14-$C14+1),0) -> 200 | U14: =IF(AND(8>=$C14,8<=$D14),($I14+($J14-$I14)*('02_Assumptions'!$C$8-1)/3)/($D14-$C14+1),0) -> 0 | V14: =IF(AND(9>=$C14,9<=$D14),($I14+($J14-$I14)*('02_Assumptions'!$C$8-1)/3)/($D14-$C14+1),0) -> 0 | W14: =IF(AND(10>=$C14,10<=$D14),($I14+($J14-$I14)*('02_Assumptions'!$C$8-1)/3)/($D14-$C14+1),0) -> 0 | X14: =IF(AND(11>=$C14,11<=$D14),($I14+($J14-$I14)*('02_Assumptions'!$C$8-1)/3)/($D14-$C14+1),0) -> 0 | Y14: =IF(AND(12>=$C14,12<=$D14),($I14+($J14-$I14)*('02_Assumptions'!$C$8-1)/3)/($D14-$C14+1),0) -> 0 | Z14: =(I14+(J14-I14)*('02_Assumptions'!$C$8-1)/3)/(D14-C14+1)/'02_Assumptions'!$C$9 -> 8
A15: Layout | B15: Staking rows/contours | C15: 5 | D15: 7 | E15: ha net | F15: ='02_Assumptions'!$C$6*'02_Assumptions'!$C$7 -> 88 | G15: ='02_Assumptions'!$C$6*'02_Assumptions'!$C$7 -> 88 | H15: 5 | I15: =F15*H15 -> 440 | J15: =G15*H15 -> 440 | K15: =I15*'02_Assumptions'!$C$60 -> 52800000 | L15: =J15*'02_Assumptions'!$C$60 -> 52800000 | M15: Survey pegs/rope | N15: =IF(AND(1>=$C15,1<=$D15),($I15+($J15-$I15)*('02_Assumptions'!$C$8-1)/3)/($D15-$C15+1),0) -> 0 | O15: =IF(AND(2>=$C15,2<=$D15),($I15+($J15-$I15)*('02_Assumptions'!$C$8-1)/3)/($D15-$C15+1),0) -> 0 | P15: =IF(AND(3>=$C15,3<=$D15),($I15+($J15-$I15)*('02_Assumptions'!$C$8-1)/3)/($D15-$C15+1),0) -> 0 | Q15: =IF(AND(4>=$C15,4<=$D15),($I15+($J15-$I15)*('02_Assumptions'!$C$8-1)/3)/($D15-$C15+1),0) -> 0 | R15: =IF(AND(5>=$C15,5<=$D15),($I15+($J15-$I15)*('02_Assumptions'!$C$8-1)/3)/($D15-$C15+1),0) -> 146.66667 | S15: =IF(AND(6>=$C15,6<=$D15),($I15+($J15-$I15)*('02_Assumptions'!$C$8-1)/3)/($D15-$C15+1),0) -> 146.66667 | T15: =IF(AND(7>=$C15,7<=$D15),($I15+($J15-$I15)*('02_Assumptions'!$C$8-1)/3)/($D15-$C15+1),0) -> 146.66667 | U15: =IF(AND(8>=$C15,8<=$D15),($I15+($J15-$I15)*('02_Assumptions'!$C$8-1)/3)/($D15-$C15+1),0) -> 0 | V15: =IF(AND(9>=$C15,9<=$D15),($I15+($J15-$I15)*('02_Assumptions'!$C$8-1)/3)/($D15-$C15+1),0) -> 0 | W15: =IF(AND(10>=$C15,10<=$D15),($I15+($J15-$I15)*('02_Assumptions'!$C$8-1)/3)/($D15-$C15+1),0) -> 0 | X15: =IF(AND(11>=$C15,11<=$D15),($I15+($J15-$I15)*('02_Assumptions'!$C$8-1)/3)/($D15-$C15+1),0) -> 0 | Y15: =IF(AND(12>=$C15,12<=$D15),($I15+($J15-$I15)*('02_Assumptions'!$C$8-1)/3)/($D15-$C15+1),0) -> 0 | Z15: =(I15+(J15-I15)*('02_Assumptions'!$C$8-1)/3)/(D15-C15+1)/'02_Assumptions'!$C$9 -> 5.8666667
A16: Soil | B16: Spread compost/manure/dolomite | C16: 6 | D16: 8 | E16: ha net | F16: ='02_Assumptions'!$C$6*'02_Assumptions'!$C$7 -> 88 | G16: ='02_Assumptions'!$C$6*'02_Assumptions'!$C$7 -> 88 | H16: 8 | I16: =F16*H16 -> 704 | J16: =G16*H16 -> 704 | K16: =I16*'02_Assumptions'!$C$60 -> 84480000 | L16: =J16*'02_Assumptions'!$C$60 -> 84480000 | M16: Tractor + hand spread | N16: =IF(AND(1>=$C16,1<=$D16),($I16+($J16-$I16)*('02_Assumptions'!$C$8-1)/3)/($D16-$C16+1),0) -> 0 | O16: =IF(AND(2>=$C16,2<=$D16),($I16+($J16-$I16)*('02_Assumptions'!$C$8-1)/3)/($D16-$C16+1),0) -> 0 | P16: =IF(AND(3>=$C16,3<=$D16),($I16+($J16-$I16)*('02_Assumptions'!$C$8-1)/3)/($D16-$C16+1),0) -> 0 | Q16: =IF(AND(4>=$C16,4<=$D16),($I16+($J16-$I16)*('02_Assumptions'!$C$8-1)/3)/($D16-$C16+1),0) -> 0 | R16: =IF(AND(5>=$C16,5<=$D16),($I16+($J16-$I16)*('02_Assumptions'!$C$8-1)/3)/($D16-$C16+1),0) -> 0 | S16: =IF(AND(6>=$C16,6<=$D16),($I16+($J16-$I16)*('02_Assumptions'!$C$8-1)/3)/($D16-$C16+1),0) -> 234.66667 | T16: =IF(AND(7>=$C16,7<=$D16),($I16+($J16-$I16)*('02_Assumptions'!$C$8-1)/3)/($D16-$C16+1),0) -> 234.66667 | U16: =IF(AND(8>=$C16,8<=$D16),($I16+($J16-$I16)*('02_Assumptions'!$C$8-1)/3)/($D16-$C16+1),0) -> 234.66667 | V16: =IF(AND(9>=$C16,9<=$D16),($I16+($J16-$I16)*('02_Assumptions'!$C$8-1)/3)/($D16-$C16+1),0) -> 0 | W16: =IF(AND(10>=$C16,10<=$D16),($I16+($J16-$I16)*('02_Assumptions'!$C$8-1)/3)/($D16-$C16+1),0) -> 0 | X16: =IF(AND(11>=$C16,11<=$D16),($I16+($J16-$I16)*('02_Assumptions'!$C$8-1)/3)/($D16-$C16+1),0) -> 0 | Y16: =IF(AND(12>=$C16,12<=$D16),($I16+($J16-$I16)*('02_Assumptions'!$C$8-1)/3)/($D16-$C16+1),0) -> 0 | Z16: =(I16+(J16-I16)*('02_Assumptions'!$C$8-1)/3)/(D16-C16+1)/'02_Assumptions'!$C$9 -> 9.3866667
A17: Planting | B17: Tree holes 60x60x60 | C17: 6 | D17: 8 | E17: hole | F17: ='04_Planting_Design'!$D$8+'04_Planting_Design'!$F$8 -> 9944 | G17: ='04_Planting_Design'!$D$8+'04_Planting_Design'!$F$8 -> 9944 | H17: 0.08 | I17: =F17*H17 -> 795.52 | J17: =G17*H17 -> 795.52 | K17: =I17*'02_Assumptions'!$C$60 -> 95462400 | L17: =J17*'02_Assumptions'!$C$60 -> 95462400 | M17: Earth auger + manual finishing | N17: =IF(AND(1>=$C17,1<=$D17),($I17+($J17-$I17)*('02_Assumptions'!$C$8-1)/3)/($D17-$C17+1),0) -> 0 | O17: =IF(AND(2>=$C17,2<=$D17),($I17+($J17-$I17)*('02_Assumptions'!$C$8-1)/3)/($D17-$C17+1),0) -> 0 | P17: =IF(AND(3>=$C17,3<=$D17),($I17+($J17-$I17)*('02_Assumptions'!$C$8-1)/3)/($D17-$C17+1),0) -> 0 | Q17: =IF(AND(4>=$C17,4<=$D17),($I17+($J17-$I17)*('02_Assumptions'!$C$8-1)/3)/($D17-$C17+1),0) -> 0 | R17: =IF(AND(5>=$C17,5<=$D17),($I17+($J17-$I17)*('02_Assumptions'!$C$8-1)/3)/($D17-$C17+1),0) -> 0 | S17: =IF(AND(6>=$C17,6<=$D17),($I17+($J17-$I17)*('02_Assumptions'!$C$8-1)/3)/($D17-$C17+1),0) -> 265.17333 | T17: =IF(AND(7>=$C17,7<=$D17),($I17+($J17-$I17)*('02_Assumptions'!$C$8-1)/3)/($D17-$C17+1),0) -> 265.17333 | U17: =IF(AND(8>=$C17,8<=$D17),($I17+($J17-$I17)*('02_Assumptions'!$C$8-1)/3)/($D17-$C17+1),0) -> 265.17333 | V17: =IF(AND(9>=$C17,9<=$D17),($I17+($J17-$I17)*('02_Assumptions'!$C$8-1)/3)/($D17-$C17+1),0) -> 0 | W17: =IF(AND(10>=$C17,10<=$D17),($I17+($J17-$I17)*('02_Assumptions'!$C$8-1)/3)/($D17-$C17+1),0) -> 0 | X17: =IF(AND(11>=$C17,11<=$D17),($I17+($J17-$I17)*('02_Assumptions'!$C$8-1)/3)/($D17-$C17+1),0) -> 0 | Y17: =IF(AND(12>=$C17,12<=$D17),($I17+($J17-$I17)*('02_Assumptions'!$C$8-1)/3)/($D17-$C17+1),0) -> 0 | Z17: =(I17+(J17-I17)*('02_Assumptions'!$C$8-1)/3)/(D17-C17+1)/'02_Assumptions'!$C$9 -> 10.606933
A18: Planting | B18: Banana holes 40x40x40 | C18: 6 | D18: 9 | E18: hole | F18: ='04_Planting_Design'!$H$8 -> 44000 | G18: ='04_Planting_Design'!$H$8 -> 44000 | H18: 0.025 | I18: =F18*H18 -> 1100 | J18: =G18*H18 -> 1100 | K18: =I18*'02_Assumptions'!$C$60 -> 132000000 | L18: =J18*'02_Assumptions'!$C$60 -> 132000000 | M18: Auger/manual | N18: =IF(AND(1>=$C18,1<=$D18),($I18+($J18-$I18)*('02_Assumptions'!$C$8-1)/3)/($D18-$C18+1),0) -> 0 | O18: =IF(AND(2>=$C18,2<=$D18),($I18+($J18-$I18)*('02_Assumptions'!$C$8-1)/3)/($D18-$C18+1),0) -> 0 | P18: =IF(AND(3>=$C18,3<=$D18),($I18+($J18-$I18)*('02_Assumptions'!$C$8-1)/3)/($D18-$C18+1),0) -> 0 | Q18: =IF(AND(4>=$C18,4<=$D18),($I18+($J18-$I18)*('02_Assumptions'!$C$8-1)/3)/($D18-$C18+1),0) -> 0 | R18: =IF(AND(5>=$C18,5<=$D18),($I18+($J18-$I18)*('02_Assumptions'!$C$8-1)/3)/($D18-$C18+1),0) -> 0 | S18: =IF(AND(6>=$C18,6<=$D18),($I18+($J18-$I18)*('02_Assumptions'!$C$8-1)/3)/($D18-$C18+1),0) -> 275 | T18: =IF(AND(7>=$C18,7<=$D18),($I18+($J18-$I18)*('02_Assumptions'!$C$8-1)/3)/($D18-$C18+1),0) -> 275 | U18: =IF(AND(8>=$C18,8<=$D18),($I18+($J18-$I18)*('02_Assumptions'!$C$8-1)/3)/($D18-$C18+1),0) -> 275 | V18: =IF(AND(9>=$C18,9<=$D18),($I18+($J18-$I18)*('02_Assumptions'!$C$8-1)/3)/($D18-$C18+1),0) -> 275 | W18: =IF(AND(10>=$C18,10<=$D18),($I18+($J18-$I18)*('02_Assumptions'!$C$8-1)/3)/($D18-$C18+1),0) -> 0 | X18: =IF(AND(11>=$C18,11<=$D18),($I18+($J18-$I18)*('02_Assumptions'!$C$8-1)/3)/($D18-$C18+1),0) -> 0 | Y18: =IF(AND(12>=$C18,12<=$D18),($I18+($J18-$I18)*('02_Assumptions'!$C$8-1)/3)/($D18-$C18+1),0) -> 0 | Z18: =(I18+(J18-I18)*('02_Assumptions'!$C$8-1)/3)/(D18-C18+1)/'02_Assumptions'!$C$9 -> 11
A19: Planting | B19: Plant coconut & durian | C19: 8 | D19: 10 | E19: plant | F19: ='04_Planting_Design'!$D$8+'04_Planting_Design'!$F$8 -> 9944 | G19: ='04_Planting_Design'!$D$8+'04_Planting_Design'!$F$8 -> 9944 | H19: 0.04 | I19: =F19*H19 -> 397.76 | J19: =G19*H19 -> 397.76 | K19: =I19*'02_Assumptions'!$C$60 -> 47731200 | L19: =J19*'02_Assumptions'!$C$60 -> 47731200 | M19: Handle graft union carefully | N19: =IF(AND(1>=$C19,1<=$D19),($I19+($J19-$I19)*('02_Assumptions'!$C$8-1)/3)/($D19-$C19+1),0) -> 0 | O19: =IF(AND(2>=$C19,2<=$D19),($I19+($J19-$I19)*('02_Assumptions'!$C$8-1)/3)/($D19-$C19+1),0) -> 0 | P19: =IF(AND(3>=$C19,3<=$D19),($I19+($J19-$I19)*('02_Assumptions'!$C$8-1)/3)/($D19-$C19+1),0) -> 0 | Q19: =IF(AND(4>=$C19,4<=$D19),($I19+($J19-$I19)*('02_Assumptions'!$C$8-1)/3)/($D19-$C19+1),0) -> 0 | R19: =IF(AND(5>=$C19,5<=$D19),($I19+($J19-$I19)*('02_Assumptions'!$C$8-1)/3)/($D19-$C19+1),0) -> 0 | S19: =IF(AND(6>=$C19,6<=$D19),($I19+($J19-$I19)*('02_Assumptions'!$C$8-1)/3)/($D19-$C19+1),0) -> 0 | T19: =IF(AND(7>=$C19,7<=$D19),($I19+($J19-$I19)*('02_Assumptions'!$C$8-1)/3)/($D19-$C19+1),0) -> 0 | U19: =IF(AND(8>=$C19,8<=$D19),($I19+($J19-$I19)*('02_Assumptions'!$C$8-1)/3)/($D19-$C19+1),0) -> 132.58667 | V19: =IF(AND(9>=$C19,9<=$D19),($I19+($J19-$I19)*('02_Assumptions'!$C$8-1)/3)/($D19-$C19+1),0) -> 132.58667 | W19: =IF(AND(10>=$C19,10<=$D19),($I19+($J19-$I19)*('02_Assumptions'!$C$8-1)/3)/($D19-$C19+1),0) -> 132.58667 | X19: =IF(AND(11>=$C19,11<=$D19),($I19+($J19-$I19)*('02_Assumptions'!$C$8-1)/3)/($D19-$C19+1),0) -> 0 | Y19: =IF(AND(12>=$C19,12<=$D19),($I19+($J19-$I19)*('02_Assumptions'!$C$8-1)/3)/($D19-$C19+1),0) -> 0 | Z19: =(I19+(J19-I19)*('02_Assumptions'!$C$8-1)/3)/(D19-C19+1)/'02_Assumptions'!$C$9 -> 5.3034667
A20: Planting | B20: Plant banana | C20: 8 | D20: 10 | E20: plant | F20: ='04_Planting_Design'!$H$8 -> 44000 | G20: ='04_Planting_Design'!$H$8 -> 44000 | H20: 0.015 | I20: =F20*H20 -> 660 | J20: =G20*H20 -> 660 | K20: =I20*'02_Assumptions'!$C$60 -> 79200000 | L20: =J20*'02_Assumptions'!$C$60 -> 79200000 | M20: Two planting waves | N20: =IF(AND(1>=$C20,1<=$D20),($I20+($J20-$I20)*('02_Assumptions'!$C$8-1)/3)/($D20-$C20+1),0) -> 0 | O20: =IF(AND(2>=$C20,2<=$D20),($I20+($J20-$I20)*('02_Assumptions'!$C$8-1)/3)/($D20-$C20+1),0) -> 0 | P20: =IF(AND(3>=$C20,3<=$D20),($I20+($J20-$I20)*('02_Assumptions'!$C$8-1)/3)/($D20-$C20+1),0) -> 0 | Q20: =IF(AND(4>=$C20,4<=$D20),($I20+($J20-$I20)*('02_Assumptions'!$C$8-1)/3)/($D20-$C20+1),0) -> 0 | R20: =IF(AND(5>=$C20,5<=$D20),($I20+($J20-$I20)*('02_Assumptions'!$C$8-1)/3)/($D20-$C20+1),0) -> 0 | S20: =IF(AND(6>=$C20,6<=$D20),($I20+($J20-$I20)*('02_Assumptions'!$C$8-1)/3)/($D20-$C20+1),0) -> 0 | T20: =IF(AND(7>=$C20,7<=$D20),($I20+($J20-$I20)*('02_Assumptions'!$C$8-1)/3)/($D20-$C20+1),0) -> 0 | U20: =IF(AND(8>=$C20,8<=$D20),($I20+($J20-$I20)*('02_Assumptions'!$C$8-1)/3)/($D20-$C20+1),0) -> 220 | V20: =IF(AND(9>=$C20,9<=$D20),($I20+($J20-$I20)*('02_Assumptions'!$C$8-1)/3)/($D20-$C20+1),0) -> 220 | W20: =IF(AND(10>=$C20,10<=$D20),($I20+($J20-$I20)*('02_Assumptions'!$C$8-1)/3)/($D20-$C20+1),0) -> 220 | X20: =IF(AND(11>=$C20,11<=$D20),($I20+($J20-$I20)*('02_Assumptions'!$C$8-1)/3)/($D20-$C20+1),0) -> 0 | Y20: =IF(AND(12>=$C20,12<=$D20),($I20+($J20-$I20)*('02_Assumptions'!$C$8-1)/3)/($D20-$C20+1),0) -> 0 | Z20: =(I20+(J20-I20)*('02_Assumptions'!$C$8-1)/3)/(D20-C20+1)/'02_Assumptions'!$C$9 -> 8.8
